Workbook
Name tsat: #REF!
Name ngiorni: #REF!
Name imese: #REF!
Name pvs_t: #REF!
Name OLE_LINK1: Materiali!$C$2

Sheet Introduzione
B2: Politecnico di Torino - DENER
B4: CALCOLO DEI PARAMETRI TERMICI DINAMICI E DELLA PRESTAZIONE IGROTERMICA DEI COMPONENTI EDILIZI
B5: secondo le norme UNI EN ISO 13786:2008 e UNI EN ISO 13788:2003
B7: Vincenzo Corrado
B9: UNI EN ISO 13786:2008 | D9: UNI EN ISO 13788:2003
B10: La norma specifica le caratteristiche legate al comportamento termico dinamico di un componente edilizio completo. Le caratteristiche termiche di un componente in regime dinamico descrivono il suo comportamento termico quando esso è soggetto a condizioni al contorno variabili, cioè flusso termico o temperatura variabile su una o su entrambe le facce del componente. La norma UNI EN ISO 13786 considera solo condizioni al contorno sinuisodali. Le proprietà considerate sono le ammettenze termiche e le proprietà termiche di trasmissione dinamica, che mettono in relazione un flusso termico variabile ciclicamente con variazioni cicliche di temperatura. | D10: La norma definisce un metodo di riferimento per determinare la temperatura superficiale interna minima dei componenti edilizi tale da evitare crescita di muffe, in corrispondenza a valori prefissati di temperatura e umidità relativa interna; il metodo può essere anche utilizzato per la previsione del rischio di altri problemi di condensazione superficiale. Inoltre viene indicato il metodo per la valutazione del rischio di condensazione interstiziale dovuta alla diffusione del vapore acqueo e le relative condizioni al contorno da utilizzare nei calcoli. Il metodo usato assume che l’umidità da costruzione si sia asciugata e non tiene conto di altri fenomeni fisici (risalita capillare, variazione con l’umidità dei parametri, termofisica, ecc.).
B11: L'ammettenza termica (interna o esterna) correla il flusso termico a variazioni di temperatura sullo stesso lato del componente. All'ammettenza è legata la capacità termica areica (interna o esterna) che quantifica la proprietà di accumulo termico del componente. Le proprietà termiche di trasmissione dinamica (trasmittanza termica periodica, fattore di attenuazione) correlano le grandezze fisiche relative ad una faccia del componente con quelle relative alla faccia opposta. Le caratteristiche termiche dinamiche definite in questa norma possono essere usate nelle specifiche di prodotto di componenti edilizi completi. Esse possono anche essere usate nel calcolo della temperatura interna di un ambiente, del carico di picco giornaliero, dei fabbisogni energetici di riscaldamento o raffrescamento, degli effetti del riscaldamento o del raffrescamento intermittente. | D11: DATI DI INGRESSO È necessaro specificare i seguenti dati: - tipo di componente (chiusura verticale, chiusura orizzontale inferiore, ... ) e per ogni strato del componente: - spessore (s); - massa volumica (r); - fattore di resistenza al vapore (m); - calore specifico (c); - conducibilità termica (l) oppure resistenza termica (R).

Sheet Caratteristiche componente
B2: Tipo di componente | D2: Chiusura superiore
B4: Stratigrafia | D4: s | E4: r | F4: m | G4: c | H4: l | I4: R | J4: opz. | AB4: Tipo di componente | AC4: Rsi | AD4: Rse
B5: (int-est) | D5: [cm] | E5: [kg/m3] | F5: [-] | G5: [J/kg°C] | H5: [W/m°C] | I5: [m2°C/W] | J5: l®R | M5: Parametro | N5: Modulo | P5: Sfasamento | AB5: Chiusura verticale | AC5: 0.13 | AD5: 0.04
B6: Strato liminare interno | I6: =$AC$13 -> 0.1 | M6: Ammettenza termica interna (Yii) | N6: ='Calcoli componente'!$L$37 -> #DIV/0! | O6: W/(m2K) | P6: ='Calcoli componente'!K37 -> #DIV/0! | Q6: h | AB6: Chiusura orizzontale inferiore | AC6: 0.17 | AD6: 0.04
B7: =ROMAN(1) -> I | C7: intonaco | D7: 1 | H7: 0.9 | M7: Ammettenza termica esterna (Yee) | N7: ='Calcoli componente'!$L$44 -> #DIV/0! | O7: W/(m2K) | P7: ='Calcoli componente'!K44 -> #DIV/0! | Q7: h | AB7: Chiusura orizzontale su spazi esterni | AC7: 0.17 | AD7: 0.04
B8: =ROMAN(2) -> II | C8: solaio | D8: 18 | I8: 0.3 | M8: Trasmittanza termica periodica (Yie) | N8: ='Calcoli componente'!$L$30 -> #DIV/0! | O8: W/(m2K) | P8: ='Calcoli componente'!K30 -> #DIV/0! | Q8: h | AB8: Chiusura superiore | AC8: 0.1 | AD8: 0.04
B9: =ROMAN(3) -> III | C9: iso | D9: 4 | H9: 0.044 | M9: Capacità termica areica interna (ki) | N9: ='Calcoli componente'!$E$37 -> #DIV/0! | O9: kJ/(m2K) | AB9: Partizione verticale | AC9: 0.13 | AD9: 0.13
B10: =ROMAN(4) -> IV | M10: Capacità termica areica esterna (ke) | N10: ='Calcoli componente'!$E$44 -> #DIV/0! | O10: kJ/(m2K) | AB10: Partizione orizzontale | AC10: 0.13 | AD10: 0.13
B11: =ROMAN(5) -> V | M11: Resistenza termica (R) | N11: ='Calcoli componente'!$K$26 -> 1.360202 | O11: (m2K)/W
B12: =ROMAN(6) -> VI | M12: Trasmittanza termica (U) | N12: ='Calcoli componente'!$L$26 -> 0.73518491 | O12: W/(m2K) | AB12: Tipo di componente | AC12: Rsi | AD12: Rse
B13: =ROMAN(7) -> VII | M13: Fattore di attenuazione (f) | N13: ='Calcoli componente'!$L$33 -> #DIV/0! | AB13: =D2 -> Chiusura superiore | AC13: =DGET($AB$4:$AD$10,"Rsi",$AB$12:$AB$13) -> 0.1 | AD13: =DGET($AB$4:$AD$10,"Rse",$AB$12:$AB$13) -> 0.04
B14: =ROMAN(8) -> VIII
B15: =ROMAN(9) -> IX | M15: Spessore (s) | N15: ='Calcoli componente'!C17 -> 23 | O15: cm
B16: =ROMAN(10) -> X | M16: Massa superficiale (m) | N16: ='Calcoli componente'!I17 -> 0 | O16: kg/m2
B17: Strato liminare esterno | I17: =$AD$13 -> 0.04 | M17: Sfasamento (j) | N17: =ABS((SIGN($P$8)*(ABS($P$8)/24-INT(ABS($P$8)/24))-IF(AND($P$8>0,(ABS($P$8)/24-INT(ABS($P$8)/24))<>0),1,0))*24) -> #DIV/0! | O17: h
M20: LEGENDA
M21: s = spessore
M22: r = massa volumica
M23: m = fattore di resistenza al vapore
M24: c = calore specifico
M25: l = conducibilità termica
M26: R = resistenza termica

Sheet Grafici
A38: q* = flusso termico areico per un componente fittizio con pari trasmittanza termica (U), ma senza accumulo di calore

Sheet Calcoli componente
A4: Stratigrafia | C4: Spessore | D4: Proprietà materiali | I4: Caratteristiche strati | X4: Z11 | AC4: Z12 | AH4: Z21 | AM4: Z22
C5: s | D5: r | E5: m | F5: c | G5: l | H5: d | I5: m | J5: sd | K5: R | L5: L | M5: C | O5: TTCi | P5: TTCe | R5: d | S5: x | T5: cosh(x)·cos(x) | U5: senh(x)·sen(x) | V5: senh(x)·cos(x) | W5: cosh(x)·sen(x) | X5: reale | Y5: immag. | Z5: modulo | AA5: fase | AB5: fase | AC5: reale | AD5: immag. | AE5: modulo | AF5: fase | AG5: fase | AH5: reale | AI5: immag. | AJ5: modulo | AK5: fase | AL5: fase | AM5: reale | AN5: immag. | AO5: modulo | AP5: fase | AQ5: fase
A6: (int-est) | C6: [cm] | D6: [kg/m3] | E6: [-] | F6: [J/kg°C] | G6: [W/m°C] | H6: [m2/s] | I6: [kg/m2] | J6: [m] | K6: [m2°C/W] | L6: [W/m2°C] | M6: [kJ/m2°C] | O6: [s] | P6: [s] | R6: [m] | S6: [-] | T6: [-] | U6: [-] | V6: [-] | W6: [-] | X6: [-] | Y6: [-] | Z6: [-] | AA6: [°] | AB6: [h] | AC6: [m2°C/W] | AD6: [m2°C/W] | AE6: [m2°C/W] | AF6: [°] | AG6: [h] | AH6: [W/m2°C] | AI6: [W/m2°C] | AJ6: [W/m2°C] | AK6: [°] | AL6: [h] | AM6: [-] | AN6: [-] | AO6: [-] | AP6: [°] | AQ6: [h]
A7: =ROMAN(1) -> I | B7: =IF('Caratteristiche componente'!C7<>"",'Caratteristiche componente'!C7,"") -> intonaco | C7: ='Caratteristiche componente'!D7 -> 1 | D7: =IF('Caratteristiche componente'!E7<>"",'Caratteristiche componente'!E7,"") | E7: =IF('Caratteristiche componente'!F7<>"",'Caratteristiche componente'!F7,"") | F7: =IF('Caratteristiche componente'!G7<>"",'Caratteristiche componente'!G7,"") | G7: =IF('Caratteristiche componente'!H7<>"",'Caratteristiche componente'!H7,IF('Caratteristiche componente'!I7<>"",C7/100/'Caratteristiche componente'!I7,"")) -> 0.9 | H7: =IF($C7>0,IF(OR($B7="intercapedine",$B7="aria"),$C7/100/$K7,$G7)/($D7*$F7),"") -> #DIV/0! | I7: =IF($C7>0,$C7/100*$D7,0) -> 0 | J7: =IF($C7>0,IF(OR('Caratteristiche componente'!$C7="intercapedine",'Caratteristiche componente'!$C7="aria",'Caratteristiche componente'!$C7="intercapedine d'aria"),0.01,$C7/100*$E7),0) -> 0 | K7: =IF($C7>0,IF(OR($B7="*intercapedine",$B7="*aria"),0.158,$C7/100/$G7),0) -> 0.011111111 | L7: =IF($C7>0,1/$K7,"") -> 90 | M7: =IF($C7>0,$I7*$F7,0) -> 0 | O7: =$M7*($K$22+$K$16+$K$15+$K$14+$K$13+$K$12+$K$11+$K$10+$K$9+$K$8+$K7/2) -> 0 | P7: =$M7*($K$21+$K7/2) -> 0 | R7: =IF($C7>0,SQRT($H7*($R$26*3600)/PI()),0) -> #DIV/0! | S7: =IF($C7>0,($C7/100)/R7,0) -> #DIV/0! | T7: =COSH($S7)*COS($S7) -> #DIV/0! | U7: =SINH($S7)*SIN($S7) -> #DIV/0! | V7: =SINH($S7)*COS($S7) -> #DIV/0! | W7: =COSH($S7)*SIN($S7) -> #DIV/0! | X7: =$T7 -> #DIV/0! | Y7: =$U7 -> #DIV/0! | Z7: =SQRT(X7^2+Y7^2) -> #DIV/0! | AA7: =DEGREES(IF(Y7<>0,ATAN2(X7,Y7),0)) -> #DIV/0! | AB7: =AA7*$R$26/360 -> #DIV/0! | AC7: =IF($C7>0,-($R7/2/$G7)*($V7+$W7),0) -> #DIV/0! | AD7: =IF($C7>0,-($R7/2/$G7)*($W7-$V7),0) -> #DIV/0! | AE7: =SQRT(AC7^2+AD7^2) -> #DIV/0! | AF7: =DEGREES(IF(AD7<>0,ATAN2(AC7,AD7),0)) -> #DIV/0! | AG7: =AF7*$R$26/360 -> #DIV/0! | AH7: =IF($C7>0,-($G7/$R7)*($V7-$W7),0) -> #DIV/0! | AI7: =IF($C7>0,-($G7/$R7)*($V7+$W7),0) -> #DIV/0! | AJ7: =SQRT(AH7^2+AI7^2) -> #DIV/0! | AK7: =DEGREES(IF(AI7<>0,ATAN2(AH7,AI7),0)) -> #DIV/0! | AL7: =AK7*$R$26/360 -> #DIV/0! | AM7: =$T7 -> #DIV/0! | AN7: =$U7 -> #DIV/0! | AO7: =Z7 -> #DIV/0! | AP7: =DEGREES(IF(AN7<>0,ATAN2(AM7,AN7),0)) -> #DIV/0! | AQ7: =AP7*$R$26/360 -> #DIV/0!
A8: =ROMAN(2) -> II | B8: =IF('Caratteristiche componente'!C8<>"",'Caratteristiche componente'!C8,"") -> solaio | C8: ='Caratteristiche componente'!D8 -> 18 | D8: =IF('Caratteristiche componente'!E8<>"",'Caratteristiche componente'!E8,"") | E8: =IF('Caratteristiche componente'!F8<>"",'Caratteristiche componente'!F8,"") | F8: =IF('Caratteristiche componente'!G8<>"",'Caratteristiche componente'!G8,"") | G8: =IF('Caratteristiche componente'!H8<>"",'Caratteristiche componente'!H8,IF('Caratteristiche componente'!I8<>"",C8/100/'Caratteristiche componente'!I8,"")) -> 0.6 | H8: =IF($C8>0,IF(OR($B8="intercapedine",$B8="aria"),$C8/100/$K8,$G8)/($D8*$F8),"") -> #DIV/0! | I8: =IF($C8>0,$C8/100*$D8,0) -> 0 | J8: =IF($C8>0,IF(OR('Caratteristiche componente'!$C8="intercapedine",'Caratteristiche componente'!$C8="aria",'Caratteristiche componente'!$C8="intercapedine d'aria"),0.01,$C8/100*$E8),0) -> 0 | K8: =IF($C8>0,IF(OR($B8="*intercapedine",$B8="*aria"),0.158,$C8/100/$G8),0) -> 0.3 | L8: =IF($C8>0,1/$K8,"") -> 3.3333333 | M8: =IF($C8>0,$I8*$F8,0) -> 0 | O8: =$M8*($K$22+$K$16+$K$15+$K$14+$K$13+$K$12+$K$11+$K$10+$K$9+$K8/2) -> 0 | P8: =$M8*($K$21+$K$7+$K8/2) -> 0 | R8: =IF($C8>0,SQRT($H8*($R$26*3600)/PI()),0) -> #DIV/0! | S8: =IF($C8>0,($C8/100)/R8,0) -> #DIV/0! | T8: =COSH($S8)*COS($S8) -> #DIV/0! | U8: =SINH($S8)*SIN($S8) -> #DIV/0! | V8: =SINH($S8)*COS($S8) -> #DIV/0! | W8: =COSH($S8)*SIN($S8) -> #DIV/0! | X8: =$T8 -> #DIV/0! | Y8: =$U8 -> #DIV/0! | Z8: =SQRT(X8^2+Y8^2) -> #DIV/0! | AA8: =DEGREES(IF(Y8<>0,ATAN2(X8,Y8),0)) -> #DIV/0! | AB8: =AA8*$R$26/360 -> #DIV/0! | AC8: =IF($C8>0,-($R8/2/$G8)*($V8+$W8),0) -> #DIV/0! | AD8: =IF($C8>0,-($R8/2/$G8)*($W8-$V8),0) -> #DIV/0! | AE8: =SQRT(AC8^2+AD8^2) -> #DIV/0! | AF8: =DEGREES(IF(AD8<>0,ATAN2(AC8,AD8),0)) -> #DIV/0! | AG8: =AF8*$R$26/360 -> #DIV/0! | AH8: =IF($C8>0,-($G8/$R8)*($V8-$W8),0) -> #DIV/0! | AI8: =IF($C8>0,-($G8/$R8)*($V8+$W8),0) -> #DIV/0! | AJ8: =SQRT(AH8^2+AI8^2) -> #DIV/0! | AK8: =DEGREES(IF(AI8<>0,ATAN2(AH8,AI8),0)) -> #DIV/0! | AL8: =AK8*$R$26/360 -> #DIV/0! | AM8: =$T8 -> #DIV/0! | AN8: =$U8 -> #DIV/0! | AO8: =Z8 -> #DIV/0! | AP8: =DEGREES(IF(AN8<>0,ATAN2(AM8,AN8),0)) -> #DIV/0! | AQ8: =AP8*$R$26/360 -> #DIV/0!
A9: =ROMAN(3) -> III | B9: =IF('Caratteristiche componente'!C9<>"",'Caratteristiche componente'!C9,"") -> iso | C9: ='Caratteristiche componente'!D9 -> 4 | D9: =IF('Caratteristiche componente'!E9<>"",'Caratteristiche componente'!E9,"") | E9: =IF('Caratteristiche componente'!F9<>"",'Caratteristiche componente'!F9,"") | F9: =IF('Caratteristiche componente'!G9<>"",'Caratteristiche componente'!G9,"") | G9: =IF('Caratteristiche componente'!H9<>"",'Caratteristiche componente'!H9,IF('Caratteristiche componente'!I9<>"",C9/100/'Caratteristiche componente'!I9,"")) -> 0.044 | H9: =IF($C9>0,IF(OR($B9="intercapedine",$B9="aria"),$C9/100/$K9,$G9)/($D9*$F9),"") -> #DIV/0! | I9: =IF($C9>0,$C9/100*$D9,0) -> 0 | J9: =IF($C9>0,IF(OR('Caratteristiche componente'!$C9="intercapedine",'Caratteristiche componente'!$C9="aria",'Caratteristiche componente'!$C9="intercapedine d'aria"),0.01,$C9/100*$E9),0) -> 0 | K9: =IF($C9>0,IF(OR($B9="*intercapedine",$B9="*aria"),0.158,$C9/100/$G9),0) -> 0.90909091 | L9: =IF($C9>0,1/$K9,"") -> 1.1 | M9: =IF($C9>0,$I9*$F9,0) -> 0 | O9: =$M9*($K$22+$K$16+$K$15+$K$14+$K$13+$K$12+$K$11+$K$10+$K9/2) -> 0 | P9: =$M9*($K$21+$K$7+$K$8+$K9/2) -> 0 | R9: =IF($C9>0,SQRT($H9*($R$26*3600)/PI()),0) -> #DIV/0! | S9: =IF($C9>0,($C9/100)/R9,0) -> #DIV/0! | T9: =COSH($S9)*COS($S9) -> #DIV/0! | U9: =SINH($S9)*SIN($S9) -> #DIV/0! | V9: =SINH($S9)*COS($S9) -> #DIV/0! | W9: =COSH($S9)*SIN($S9) -> #DIV/0! | X9: =$T9 -> #DIV/0! | Y9: =$U9 -> #DIV/0! | Z9: =SQRT(X9^2+Y9^2) -> #DIV/0! | AA9: =DEGREES(IF(Y9<>0,ATAN2(X9,Y9),0)) -> #DIV/0! | AB9: =AA9*$R$26/360 -> #DIV/0! | AC9: =IF($C9>0,-($R9/2/$G9)*($V9+$W9),0) -> #DIV/0! | AD9: =IF($C9>0,-($R9/2/$G9)*($W9-$V9),0) -> #DIV/0! | AE9: =SQRT(AC9^2+AD9^2) -> #DIV/0! | AF9: =DEGREES(IF(AD9<>0,ATAN2(AC9,AD9),0)) -> #DIV/0! | AG9: =AF9*$R$26/360 -> #DIV/0! | AH9: =IF($C9>0,-($G9/$R9)*($V9-$W9),0) -> #DIV/0! | AI9: =IF($C9>0,-($G9/$R9)*($V9+$W9),0) -> #DIV/0! | AJ9: =SQRT(AH9^2+AI9^2) -> #DIV/0! | AK9: =DEGREES(IF(AI9<>0,ATAN2(AH9,AI9),0)) -> #DIV/0! | AL9: =AK9*$R$26/360 -> #DIV/0! | AM9: =$T9 -> #DIV/0! | AN9: =$U9 -> #DIV/0! | AO9: =Z9 -> #DIV/0! | AP9: =DEGREES(IF(AN9<>0,ATAN2(AM9,AN9),0)) -> #DIV/0! | AQ9: =AP9*$R$26/360 -> #DIV/0!
A10: =ROMAN(4) -> IV | B10: =IF('Caratteristiche componente'!C10<>"",'Caratteristiche componente'!C10,"") | C10: ='Caratteristiche componente'!D10 | D10: =IF('Caratteristiche componente'!E10<>"",'Caratteristiche componente'!E10,"") | E10: =IF('Caratteristiche componente'!F10<>"",'Caratteristiche componente'!F10,"") | F10: =IF('Caratteristiche componente'!G10<>"",'Caratteristiche componente'!G10,"") | G10: =IF('Caratteristiche componente'!H10<>"",'Caratteristiche componente'!H10,IF('Caratteristiche componente'!I10<>"",C10/100/'Caratteristiche componente'!I10,"")) | H10: =IF($C10>0,IF(OR($B10="intercapedine",$B10="aria"),$C10/100/$K10,$G10)/($D10*$F10),"") | I10: =IF($C10>0,$C10/100*$D10,0) -> 0 | J10: =IF($C10>0,IF(OR('Caratteristiche componente'!$C10="intercapedine",'Caratteristiche componente'!$C10="aria",'Caratteristiche componente'!$C10="intercapedine d'aria"),0.01,$C10/100*$E10),0) -> 0 | K10: =IF($C10>0,IF(OR($B10="*intercapedine",$B10="*aria"),0.158,$C10/100/$G10),0) -> 0 | L10: =IF($C10>0,1/$K10,"") | M10: =IF($C10>0,$I10*$F10,0) -> 0 | O10: =$M10*($K$22+$K$16+$K$15+$K$14+$K$13+$K$12+$K$11+$K10/2) -> 0 | P10: =$M10*($K$21+$K$7+$K$8+$K$9+$K10/2) -> 0 | R10: =IF($C10>0,SQRT($H10*($R$26*3600)/PI()),0) -> 0 | S10: =IF($C10>0,($C10/100)/R10,0) -> 0 | T10: =COSH($S10)*COS($S10) -> 1 | U10: =SINH($S10)*SIN($S10) -> 0 | V10: =SINH($S10)*COS($S10) -> 0 | W10: =COSH($S10)*SIN($S10) -> 0 | X10: =$T10 -> 1 | Y10: =$U10 -> 0 | Z10: =SQRT(X10^2+Y10^2) -> 1 | AA10: =DEGREES(IF(Y10<>0,ATAN2(X10,Y10),0)) -> 0 | AB10: =AA10*$R$26/360 -> 0 | AC10: =IF($C10>0,-($R10/2/$G10)*($V10+$W10),0) -> 0 | AD10: =IF($C10>0,-($R10/2/$G10)*($W10-$V10),0) -> 0 | AE10: =SQRT(AC10^2+AD10^2) -> 0 | AF10: =DEGREES(IF(AD10<>0,ATAN2(AC10,AD10),0)) -> 0 | AG10: =AF10*$R$26/360 -> 0 | AH10: =IF($C10>0,-($G10/$R10)*($V10-$W10),0) -> 0 | AI10: =IF($C10>0,-($G10/$R10)*($V10+$W10),0) -> 0 | AJ10: =SQRT(AH10^2+AI10^2) -> 0 | AK10: =DEGREES(IF(AI10<>0,ATAN2(AH10,AI10),0)) -> 0 | AL10: =AK10*$R$26/360 -> 0 | AM10: =$T10 -> 1 | AN10: =$U10 -> 0 | AO10: =Z10 -> 1 | AP10: =DEGREES(IF(AN10<>0,ATAN2(AM10,AN10),0)) -> 0 | AQ10: =AP10*$R$26/360 -> 0
A11: =ROMAN(5) -> V | B11: =IF('Caratteristiche componente'!C11<>"",'Caratteristiche componente'!C11,"") | C11: ='Caratteristiche componente'!D11 | D11: =IF('Caratteristiche componente'!E11<>"",'Caratteristiche componente'!E11,"") | E11: =IF('Caratteristiche componente'!F11<>"",'Caratteristiche componente'!F11,"") | F11: =IF('Caratteristiche componente'!G11<>"",'Caratteristiche componente'!G11,"") | G11: =IF('Caratteristiche componente'!H11<>"",'Caratteristiche componente'!H11,IF('Caratteristiche componente'!I11<>"",C11/100/'Caratteristiche componente'!I11,"")) | H11: =IF($C11>0,IF(OR($B11="intercapedine",$B11="aria"),$C11/100/$K11,$G11)/($D11*$F11),"") | I11: =IF($C11>0,$C11/100*$D11,0) -> 0 | J11: =IF($C11>0,IF(OR('Caratteristiche componente'!$C11="intercapedine",'Caratteristiche componente'!$C11="aria",'Caratteristiche componente'!$C11="intercapedine d'aria"),0.01,$C11/100*$E11),0) -> 0 | K11: =IF($C11>0,IF(OR($B11="*intercapedine",$B11="*aria"),0.158,$C11/100/$G11),0) -> 0 | L11: =IF($C11>0,1/$K11,"") | M11: =IF($C11>0,$I11*$F11,0) -> 0 | O11: =$M11*($K$22+$K$16+$K$15+$K$14+$K$13+$K$12+$K11/2) -> 0 | P11: =$M11*($K$21+$K$7+$K$8+$K$9+$K$10+$K11/2) -> 0 | R11: =IF($C11>0,SQRT($H11*($R$26*3600)/PI()),0) -> 0 | S11: =IF($C11>0,($C11/100)/R11,0) -> 0 | T11: =COSH($S11)*COS($S11) -> 1 | U11: =SINH($S11)*SIN($S11) -> 0 | V11: =SINH($S11)*COS($S11) -> 0 | W11: =COSH($S11)*SIN($S11) -> 0 | X11: =$T11 -> 1 | Y11: =$U11 -> 0 | Z11: =SQRT(X11^2+Y11^2) -> 1 | AA11: =DEGREES(IF(Y11<>0,ATAN2(X11,Y11),0)) -> 0 | AB11: =AA11*$R$26/360 -> 0 | AC11: =IF($C11>0,-($R11/2/$G11)*($V11+$W11),0) -> 0 | AD11: =IF($C11>0,-($R11/2/$G11)*($W11-$V11),0) -> 0 | AE11: =SQRT(AC11^2+AD11^2) -> 0 | AF11: =DEGREES(IF(AD11<>0,ATAN2(AC11,AD11),0)) -> 0 | AG11: =AF11*$R$26/360 -> 0 | AH11: =IF($C11>0,-($G11/$R11)*($V11-$W11),0) -> 0 | AI11: =IF($C11>0,-($G11/$R11)*($V11+$W11),0) -> 0 | AJ11: =SQRT(AH11^2+AI11^2) -> 0 | AK11: =DEGREES(IF(AI11<>0,ATAN2(AH11,AI11),0)) -> 0 | AL11: =AK11*$R$26/360 -> 0 | AM11: =$T11 -> 1 | AN11: =$U11 -> 0 | AO11: =Z11 -> 1 | AP11: =DEGREES(IF(AN11<>0,ATAN2(AM11,AN11),0)) -> 0 | AQ11: =AP11*$R$26/360 -> 0
A12: =ROMAN(6) -> VI | B12: =IF('Caratteristiche componente'!C12<>"",'Caratteristiche componente'!C12,"") | C12: ='Caratteristiche componente'!D12 | D12: =IF('Caratteristiche componente'!E12<>"",'Caratteristiche componente'!E12,"") | E12: =IF('Caratteristiche componente'!F12<>"",'Caratteristiche componente'!F12,"") | F12: =IF('Caratteristiche componente'!G12<>"",'Caratteristiche componente'!G12,"") | G12: =IF('Caratteristiche componente'!H12<>"",'Caratteristiche componente'!H12,IF('Caratteristiche componente'!I12<>"",C12/100/'Caratteristiche componente'!I12,"")) | H12: =IF($C12>0,IF(OR($B12="intercapedine",$B12="aria"),$C12/100/$K12,$G12)/($D12*$F12),"") | I12: =IF($C12>0,$C12/100*$D12,0) -> 0 | J12: =IF($C12>0,IF(OR('Caratteristiche componente'!$C12="intercapedine",'Caratteristiche componente'!$C12="aria",'Caratteristiche componente'!$C12="intercapedine d'aria"),0.01,$C12/100*$E12),0) -> 0 | K12: =IF($C12>0,IF(OR($B12="*intercapedine",$B12="*aria"),0.158,$C12/100/$G12),0) -> 0 | L12: =IF($C12>0,1/$K12,"") | M12: =IF($C12>0,$I12*$F12,0) -> 0 | O12: =$M12*($K$22+$K$16+$K$15+$K$14+$K$13+$K12/2) -> 0 | P12: =$M12*($K$21+$K$7+$K$8+$K$9+$K$10+$K$11+$K12/2) -> 0 | R12: =IF($C12>0,SQRT($H12*($R$26*3600)/PI()),0) -> 0 | S12: =IF($C12>0,($C12/100)/R12,0) -> 0 | T12: =COSH($S12)*COS($S12) -> 1 | U12: =SINH($S12)*SIN($S12) -> 0 | V12: =SINH($S12)*COS($S12) -> 0 | W12: =COSH($S12)*SIN($S12) -> 0 | X12: =$T12 -> 1 | Y12: =$U12 -> 0 | Z12: =SQRT(X12^2+Y12^2) -> 1 | AA12: =DEGREES(IF(Y12<>0,ATAN2(X12,Y12),0)) -> 0 | AB12: =AA12*$R$26/360 -> 0 | AC12: =IF($C12>0,-($R12/2/$G12)*($V12+$W12),0) -> 0 | AD12: =IF($C12>0,-($R12/2/$G12)*($W12-$V12),0) -> 0 | AE12: =SQRT(AC12^2+AD12^2) -> 0 | AF12: =DEGREES(IF(AD12<>0,ATAN2(AC12,AD12),0)) -> 0 | AG12: =AF12*$R$26/360 -> 0 | AH12: =IF($C12>0,-($G12/$R12)*($V12-$W12),0) -> 0 | AI12: =IF($C12>0,-($G12/$R12)*($V12+$W12),0) -> 0 | AJ12: =SQRT(AH12^2+AI12^2) -> 0 | AK12: =DEGREES(IF(AI12<>0,ATAN2(AH12,AI12),0)) -> 0 | AL12: =AK12*$R$26/360 -> 0 | AM12: =$T12 -> 1 | AN12: =$U12 -> 0 | AO12: =Z12 -> 1 | AP12: =DEGREES(IF(AN12<>0,ATAN2(AM12,AN12),0)) -> 0 | AQ12: =AP12*$R$26/360 -> 0
A13: =ROMAN(7) -> VII | B13: =IF('Caratteristiche componente'!C13<>"",'Caratteristiche componente'!C13,"") | C13: ='Caratteristiche componente'!D13 | D13: =IF('Caratteristiche componente'!E13<>"",'Caratteristiche componente'!E13,"") | E13: =IF('Caratteristiche componente'!F13<>"",'Caratteristiche componente'!F13,"") | F13: =IF('Caratteristiche componente'!G13<>"",'Caratteristiche componente'!G13,"") | G13: =IF('Caratteristiche componente'!H13<>"",'Caratteristiche componente'!H13,IF('Caratteristiche componente'!I13<>"",C13/100/'Caratteristiche componente'!I13,"")) | H13: =IF($C13>0,IF(OR($B13="intercapedine",$B13="aria"),$C13/100/$K13,$G13)/($D13*$F13),"") | I13: =IF($C13>0,$C13/100*$D13,0) -> 0 | J13: =IF($C13>0,IF(OR('Caratteristiche componente'!$C13="intercapedine",'Caratteristiche componente'!$C13="aria",'Caratteristiche componente'!$C13="intercapedine d'aria"),0.01,$C13/100*$E13),0) -> 0 | K13: =IF($C13>0,IF(OR($B13="*intercapedine",$B13="*aria"),0.158,$C13/100/$G13),0) -> 0 | L13: =IF($C13>0,1/$K13,"") | M13: =IF($C13>0,$I13*$F13,0) -> 0 | O13: =$M13*($K$22+$K$16+$K$15+$K$14+$K13/2) -> 0 | P13: =$M13*($K$21+$K$7+$K$8+$K$9+$K$10+$K$11+$K$12+$K13/2) -> 0 | R13: =IF($C13>0,SQRT($H13*($R$26*3600)/PI()),0) -> 0 | S13: =IF($C13>0,($C13/100)/R13,0) -> 0 | T13: =COSH($S13)*COS($S13) -> 1 | U13: =SINH($S13)*SIN($S13) -> 0 | V13: =SINH($S13)*COS($S13) -> 0 | W13: =COSH($S13)*SIN($S13) -> 0 | X13: =$T13 -> 1 | Y13: =$U13 -> 0 | Z13: =SQRT(X13^2+Y13^2) -> 1 | AA13: =DEGREES(IF(Y13<>0,ATAN2(X13,Y13),0)) -> 0 | AB13: =AA13*$R$26/360 -> 0 | AC13: =IF($C13>0,-($R13/2/$G13)*($V13+$W13),0) -> 0 | AD13: =IF($C13>0,-($R13/2/$G13)*($W13-$V13),0) -> 0 | AE13: =SQRT(AC13^2+AD13^2) -> 0 | AF13: =DEGREES(IF(AD13<>0,ATAN2(AC13,AD13),0)) -> 0 | AG13: =AF13*$R$26/360 -> 0 | AH13: =IF($C13>0,-($G13/$R13)*($V13-$W13),0) -> 0 | AI13: =IF($C13>0,-($G13/$R13)*($V13+$W13),0) -> 0 | AJ13: =SQRT(AH13^2+AI13^2) -> 0 | AK13: =DEGREES(IF(AI13<>0,ATAN2(AH13,AI13),0)) -> 0 | AL13: =AK13*$R$26/360 -> 0 | AM13: =$T13 -> 1 | AN13: =$U13 -> 0 | AO13: =Z13 -> 1 | AP13: =DEGREES(IF(AN13<>0,ATAN2(AM13,AN13),0)) -> 0 | AQ13: =AP13*$R$26/360 -> 0
A14: =ROMAN(8) -> VIII | B14: =IF('Caratteristiche componente'!C14<>"",'Caratteristiche componente'!C14,"") | C14: ='Caratteristiche componente'!D14 | D14: =IF('Caratteristiche componente'!E14<>"",'Caratteristiche componente'!E14,"") | E14: =IF('Caratteristiche componente'!F14<>"",'Caratteristiche componente'!F14,"") | F14: =IF('Caratteristiche componente'!G14<>"",'Caratteristiche componente'!G14,"") | G14: =IF('Caratteristiche componente'!H14<>"",'Caratteristiche componente'!H14,IF('Caratteristiche componente'!I14<>"",C14/100/'Caratteristiche componente'!I14,"")) | H14: =IF($C14>0,IF(OR($B14="intercapedine",$B14="aria"),$C14/100/$K14,$G14)/($D14*$F14),"") | I14: =IF($C14>0,$C14/100*$D14,0) -> 0 | J14: =IF($C14>0,IF(OR('Caratteristiche componente'!$C14="intercapedine",'Caratteristiche componente'!$C14="aria",'Caratteristiche componente'!$C14="intercapedine d'aria"),0.01,$C14/100*$E14),0) -> 0 | K14: =IF($C14>0,IF(OR($B14="*intercapedine",$B14="*aria"),0.158,$C14/100/$G14),0) -> 0 | L14: =IF($C14>0,1/$K14,"") | M14: =IF($C14>0,$I14*$F14,0) -> 0 | O14: =$M14*($K$22+$K$16+$K$15+$K14/2) -> 0 | P14: =$M14*($K$21+$K$7+$K$8+$K$9+$K$10+$K$11+$K$12+$K$13+$K14/2) -> 0 | R14: =IF($C14>0,SQRT($H14*($R$26*3600)/PI()),0) -> 0 | S14: =IF($C14>0,($C14/100)/R14,0) -> 0 | T14: =COSH($S14)*COS($S14) -> 1 | U14: =SINH($S14)*SIN($S14) -> 0 | V14: =SINH($S14)*COS($S14) -> 0 | W14: =COSH($S14)*SIN($S14) -> 0 | X14: =$T14 -> 1 | Y14: =$U14 -> 0 | Z14: =SQRT(X14^2+Y14^2) -> 1 | AA14: =DEGREES(IF(Y14<>0,ATAN2(X14,Y14),0)) -> 0 | AB14: =AA14*$R$26/360 -> 0 | AC14: =IF($C14>0,-($R14/2/$G14)*($V14+$W14),0) -> 0 | AD14: =IF($C14>0,-($R14/2/$G14)*($W14-$V14),0) -> 0 | AE14: =SQRT(AC14^2+AD14^2) -> 0 | AF14: =DEGREES(IF(AD14<>0,ATAN2(AC14,AD14),0)) -> 0 | AG14: =AF14*$R$26/360 -> 0 | AH14: =IF($C14>0,-($G14/$R14)*($V14-$W14),0) -> 0 | AI14: =IF($C14>0,-($G14/$R14)*($V14+$W14),0) -> 0 | AJ14: =SQRT(AH14^2+AI14^2) -> 0 | AK14: =DEGREES(IF(AI14<>0,ATAN2(AH14,AI14),0)) -> 0 | AL14: =AK14*$R$26/360 -> 0 | AM14: =$T14 -> 1 | AN14: =$U14 -> 0 | AO14: =Z14 -> 1 | AP14: =DEGREES(IF(AN14<>0,ATAN2(AM14,AN14),0)) -> 0 | AQ14: =AP14*$R$26/360 -> 0
A15: =ROMAN(9) -> IX | B15: =IF('Caratteristiche componente'!C15<>"",'Caratteristiche componente'!C15,"") | C15: ='Caratteristiche componente'!D15 | D15: =IF('Caratteristiche componente'!E15<>"",'Caratteristiche componente'!E15,"") | E15: =IF('Caratteristiche componente'!F15<>"",'Caratteristiche componente'!F15,"") | F15: =IF('Caratteristiche componente'!G15<>"",'Caratteristiche componente'!G15,"") | G15: =IF('Caratteristiche componente'!H15<>"",'Caratteristiche componente'!H15,IF('Caratteristiche componente'!I15<>"",C15/100/'Caratteristiche componente'!I15,"")) | H15: =IF($C15>0,IF(OR($B15="intercapedine",$B15="aria"),$C15/100/$K15,$G15)/($D15*$F15),"") | I15: =IF($C15>0,$C15/100*$D15,0) -> 0 | J15: =IF($C15>0,IF(OR('Caratteristiche componente'!$C15="intercapedine",'Caratteristiche componente'!$C15="aria",'Caratteristiche componente'!$C15="intercapedine d'aria"),0.01,$C15/100*$E15),0) -> 0 | K15: =IF($C15>0,IF(OR($B15="*intercapedine",$B15="*aria"),0.158,$C15/100/$G15),0) -> 0 | L15: =IF($C15>0,1/$K15,"") | M15: =IF($C15>0,$I15*$F15,0) -> 0 | O15: =$M15*($K$22+$K$16+$K15/2) -> 0 | P15: =$M15*($K$21+$K$7+$K$8+$K$9+$K$10+$K$11+$K$12+$K$13+$K$14+$K15/2) -> 0 | R15: =IF($C15>0,SQRT($H15*($R$26*3600)/PI()),0) -> 0 | S15: =IF($C15>0,($C15/100)/R15,0) -> 0 | T15: =COSH($S15)*COS($S15) -> 1 | U15: =SINH($S15)*SIN($S15) -> 0 | V15: =SINH($S15)*COS($S15) -> 0 | W15: =COSH($S15)*SIN($S15) -> 0 | X15: =$T15 -> 1 | Y15: =$U15 -> 0 | Z15: =SQRT(X15^2+Y15^2) -> 1 | AA15: =DEGREES(IF(Y15<>0,ATAN2(X15,Y15),0)) -> 0 | AB15: =AA15*$R$26/360 -> 0 | AC15: =IF($C15>0,-($R15/2/$G15)*($V15+$W15),0) -> 0 | AD15: =IF($C15>0,-($R15/2/$G15)*($W15-$V15),0) -> 0 | AE15: =SQRT(AC15^2+AD15^2) -> 0 | AF15: =DEGREES(IF(AD15<>0,ATAN2(AC15,AD15),0)) -> 0 | AG15: =AF15*$R$26/360 -> 0 | AH15: =IF($C15>0,-($G15/$R15)*($V15-$W15),0) -> 0 | AI15: =IF($C15>0,-($G15/$R15)*($V15+$W15),0) -> 0 | AJ15: =SQRT(AH15^2+AI15^2) -> 0 | AK15: =DEGREES(IF(AI15<>0,ATAN2(AH15,AI15),0)) -> 0 | AL15: =AK15*$R$26/360 -> 0 | AM15: =$T15 -> 1 | AN15: =$U15 -> 0 | AO15: =Z15 -> 1 | AP15: =DEGREES(IF(AN15<>0,ATAN2(AM15,AN15),0)) -> 0 | AQ15: =AP15*$R$26/360 -> 0
A16: =ROMAN(10) -> X | B16: =IF('Caratteristiche componente'!C16<>"",'Caratteristiche componente'!C16,"") | C16: ='Caratteristiche componente'!D16 | D16: =IF('Caratteristiche componente'!E16<>"",'Caratteristiche componente'!E16,"") | E16: =IF('Caratteristiche componente'!F16<>"",'Caratteristiche componente'!F16,"") | F16: =IF('Caratteristiche componente'!G16<>"",'Caratteristiche componente'!G16,"") | G16: =IF('Caratteristiche componente'!H16<>"",'Caratteristiche componente'!H16,IF('Caratteristiche componente'!I16<>"",C16/100/'Caratteristiche componente'!I16,"")) | H16: =IF($C16>0,IF(OR($B16="intercapedine",$B16="aria"),$C16/100/$K16,$G16)/($D16*$F16),"") | I16: =IF($C16>0,$C16/100*$D16,0) -> 0 | J16: =IF($C16>0,IF(OR('Caratteristiche componente'!$C16="intercapedine",'Caratteristiche componente'!$C16="aria",'Caratteristiche componente'!$C16="intercapedine d'aria"),0.01,$C16/100*$E16),0) -> 0 | K16: =IF($C16>0,IF(OR($B16="*intercapedine",$B16="*aria"),0.158,$C16/100/$G16),0) -> 0 | L16: =IF($C16>0,1/$K16,"") | M16: =IF($C16>0,$I16*$F16,0) -> 0 | O16: =$M16*($K$22+$K16/2) -> 0 | P16: =$M16*($K$21+$K$7+$K$8+$K$9+$K$10+$K$11+$K$12+$K$13+$K$14+$K$15+$K16/2) -> 0 | R16: =IF($C16>0,SQRT($H16*($R$26*3600)/PI()),0) -> 0 | S16: =IF($C16>0,($C16/100)/R16,0) -> 0 | T16: =COSH($S16)*COS($S16) -> 1 | U16: =SINH($S16)*SIN($S16) -> 0 | V16: =SINH($S16)*COS($S16) -> 0 | W16: =COSH($S16)*SIN($S16) -> 0 | X16: =$T16 -> 1 | Y16: =$U16 -> 0 | Z16: =SQRT(X16^2+Y16^2) -> 1 | AA16: =DEGREES(IF(Y16<>0,ATAN2(X16,Y16),0)) -> 0 | AB16: =AA16*$R$26/360 -> 0 | AC16: =IF($C16>0,-($R16/2/$G16)*($V16+$W16),0) -> 0 | AD16: =IF($C16>0,-($R16/2/$G16)*($W16-$V16),0) -> 0 | AE16: =SQRT(AC16^2+AD16^2) -> 0 | AF16: =DEGREES(IF(AD16<>0,ATAN2(AC16,AD16),0)) -> 0 | AG16: =AF16*$R$26/360 -> 0 | AH16: =IF($C16>0,-($G16/$R16)*($V16-$W16),0) -> 0 | AI16: =IF($C16>0,-($G16/$R16)*($V16+$W16),0) -> 0 | AJ16: =SQRT(AH16^2+AI16^2) -> 0 | AK16: =DEGREES(IF(AI16<>0,ATAN2(AH16,AI16),0)) -> 0 | AL16: =AK16*$R$26/360 -> 0 | AM16: =$T16 -> 1 | AN16: =$U16 -> 0 | AO16: =Z16 -> 1 | AP16: =DEGREES(IF(AN16<>0,ATAN2(AM16,AN16),0)) -> 0 | AQ16: =AP16*$R$26/360 -> 0
A17: Totale | C17: =SUM(C$7:C$16) -> 23 | I17: =SUM(I$7:I$16) -> 0 | J17: =SUM(J$7:J$16) -> 0 | K17: =SUM(K$7:K$16) -> 1.220202 | L17: =IF($C17>0,1/$K17,"") -> 0.81953642 | M17: =SUM(M$7:M$16) -> 0 | O17: =SUM(O$7:O$16) -> 0 | P17: =SUM(P$7:P$16) -> 0
X18: Z11 | AC18: Z12 | AH18: Z21 | AM18: Z22
K19: Rs | L19: hs | X19: reale | Y19: immag. | Z19: modulo | AA19: fase | AB19: fase | AC19: reale | AD19: immag. | AE19: modulo | AF19: fase | AG19: fase | AH19: reale | AI19: immag. | AJ19: modulo | AK19: fase | AL19: fase | AM19: reale | AN19: immag. | AO19: modulo | AP19: fase | AQ19: fase
K20: [m2°C/W] | L20: [W/m2°C] | X20: [-] | Y20: [-] | Z20: [-] | AA20: [°] | AB20: [h] | AC20: [m2°C/W] | AD20: [m2°C/W] | AE20: [m2°C/W] | AF20: [°] | AG20: [h] | AH20: [W/m2°C] | AI20: [W/m2°C] | AJ20: [W/m2°C] | AK20: [°] | AL20: [h] | AM20: [-] | AN20: [-] | AO20: [-] | AP20: [°] | AQ20: [h]
A21: Strato liminare interno | K21: ='Caratteristiche componente'!$I$6 -> 0.1 | L21: =1/K21 -> 10 | V21: Strato liminare interno | X21: 1 | Y21: 0 | Z21: =SQRT(X21^2+Y21^2) -> 1 | AA21: =DEGREES(IF(Y21<>0,ATAN2(X21,Y21),0)) -> 0 | AB21: =AA21*$R$26/360 -> 0 | AC21: =-$K21 -> -0.1 | AD21: 0 | AE21: =SQRT(AC21^2+AD21^2) -> 0.1 | AF21: =DEGREES(IF(AD21<>0,ATAN2(AC21,AD21),0)) -> 0 | AG21: =AF21*$R$26/360 -> 0 | AH21: 0 | AI21: 0 | AJ21: =SQRT(AH21^2+AI21^2) -> 0 | AK21: =DEGREES(IF(AI21<>0,ATAN2(AH21,AI21),0)) -> 0 | AL21: =AK21*$R$26/360 -> 0 | AM21: 1 | AN21: 0 | AO21: =Z21 -> 1 | AP21: =DEGREES(IF(AN21<>0,ATAN2(AM21,AN21),0)) -> 0 | AQ21: =AP21*$R$26/360 -> 0
A22: Strato liminare esterno | K22: ='Caratteristiche componente'!$I$17 -> 0.04 | L22: =1/K22 -> 25 | V22: Strato liminare esterno | X22: 1 | Y22: 0 | Z22: =SQRT(X22^2+Y22^2) -> 1 | AA22: =DEGREES(IF(Y22<>0,ATAN2(X22,Y22),0)) -> 0 | AB22: =AA22*$R$26/360 -> 0 | AC22: =-$K22 -> -0.04 | AD22: 0 | AE22: =SQRT(AC22^2+AD22^2) -> 0.04 | AF22: =DEGREES(IF(AD22<>0,ATAN2(AC22,AD22),0)) -> 0 | AG22: =AF22*$R$26/360 -> 0 | AH22: 0 | AI22: 0 | AJ22: =SQRT(AH22^2+AI22^2) -> 0 | AK22: =DEGREES(IF(AI22<>0,ATAN2(AH22,AI22),0)) -> 0 | AL22: =AK22*$R$26/360 -> 0 | AM22: 1 | AN22: 0 | AO22: =Z22 -> 1 | AP22: =DEGREES(IF(AN22<>0,ATAN2(AM22,AN22),0)) -> 0 | AQ22: =AP22*$R$26/360 -> 0
K24: R | L24: U | N24: TTC | O24: TTCi | P24: TTCe | R24: T | S24: w | X24: Z11 | AC24: Z12 | AH24: Z21 | AM24: Z22 | AR24: Yii = Y11 = -Z11/Z12 | AW24: Yee = Y22 = -Z22/Z12 | BB24: Yie = Y12 = -1/Z12
K25: [m2°C/W] | L25: [W/m2°C] | N25: [h] | O25: [h] | P25: [h] | R25: [h] | S25: [rad/s] | X25: reale | Y25: immag. | Z25: modulo | AA25: fase | AB25: fase | AC25: reale | AD25: immag. | AE25: modulo | AF25: fase | AG25: fase | AH25: reale | AI25: immag. | AJ25: modulo | AK25: fase | AL25: fase | AM25: reale | AN25: immag. | AO25: modulo | AP25: fase | AQ25: fase | AR25: reale | AS25: immag. | AT25: modulo | AU25: fase | AV25: fase | AW25: reale | AX25: immag. | AY25: modulo | AZ25: fase | BA25: fase | BB25: reale | BC25: immag. | BD25: modulo | BE25: fase | BF25: fase
K26: =$K$17+$K$21+$K$22 -> 1.360202 | L26: =1/$K$26 -> 0.73518491 | N26: =M17*K26/3600 -> 0 | O26: =$O$17/3600 -> 0 | P26: =$P$17/3600 -> 0 | R26: 24 | S26: =(2*PI())/(R26*3600) -> 7.2722052e-05 | X26: [-] | Y26: [-] | Z26: [-] | AA26: [°] | AB26: [h] | AC26: [m2°C/W] | AD26: [m2°C/W] | AE26: [m2°C/W] | AF26: [°] | AG26: [h] | AH26: [W/m2°C] | AI26: [W/m2°C] | AJ26: [W/m2°C] | AK26: [°] | AL26: [h] | AM26: [-] | AN26: [-] | AO26: [-] | AP26: [°] | AQ26: [h] | AR26: [W/m2°C] | AS26: [W/m2°C] | AT26: [W/m2°C] | AU26: [°] | AV26: [h] | AW26: [W/m2°C] | AX26: [W/m2°C] | AY26: [W/m2°C] | AZ26: [°] | BA26: [h] | BB26: [W/m2°C] | BC26: [W/m2°C] | BD26: [W/m2°C] | BE26: [°] | BF26: [h]
V27: Componente | X27: ='Calcoli matriciali'!$AP$9 -> #DIV/0! | Y27: ='Calcoli matriciali'!$AQ$9 | Z27: =SQRT(X27^2+Y27^2) -> #DIV/0! | AA27: =DEGREES(IF(Y27<>0,ATAN2(X27,Y27),0)) -> 0 | AB27: =AA27*$R$26/360 -> 0 | AC27: ='Calcoli matriciali'!$AR$9 | AD27: ='Calcoli matriciali'!$AS$9 | AE27: =SQRT(AC27^2+AD27^2) -> 0 | AF27: =DEGREES(IF(AD27<>0,ATAN2(AC27,AD27),0)) -> 0 | AG27: =AF27*$R$26/360 -> 0 | AH27: ='Calcoli matriciali'!$AP$11 | AI27: ='Calcoli matriciali'!$AQ$11 | AJ27: =SQRT(AH27^2+AI27^2) -> 0 | AK27: =DEGREES(IF(AI27<>0,ATAN2(AH27,AI27),0)) -> 0 | AL27: =AK27*$R$26/360 -> 0 | AM27: ='Calcoli matriciali'!$AR$11 | AN27: ='Calcoli matriciali'!$AS$11 | AO27: =SQRT(AM27^2+AN27^2) -> 0 | AP27: =DEGREES(IF(AN27<>0,ATAN2(AM27,AN27),0)) -> 0 | AQ27: =AP27*$R$26/360 -> 0 | AR27: =-($X27*$AC27+$Y27*$AD27)/($AC27^2+$AD27^2) -> #DIV/0! | AS27: =-($Y27*$AC27-$X27*$AD27)/($AC27^2+$AD27^2) -> #DIV/0! | AT27: =SQRT(AR27^2+AS27^2) -> #DIV/0! | AU27: =DEGREES(IF(AS27<>0,ATAN2(AR27,AS27),0)) -> #DIV/0! | AV27: =AU27*$R$26/360 -> #DIV/0! | AW27: =-($AM27*$AC27+$AN27*$AD27)/($AC27^2+$AD27^2) -> #DIV/0! | AX27: =-($AN27*$AC27-$AM27*$AD27)/($AC27^2+$AD27^2) -> #DIV/0! | AY27: =SQRT(AW27^2+AX27^2) -> #DIV/0! | AZ27: =DEGREES(IF(AX27<>0,ATAN2(AW27,AX27),0)) -> #DIV/0! | BA27: =AZ27*$R$26/360 -> #DIV/0! | BB27: =-$AC27/($AC27^2+$AD27^2) -> #DIV/0! | BC27: =$AD27/($AC27^2+$AD27^2) -> #DIV/0! | BD27: =SQRT(BB27^2+BC27^2) -> #DIV/0! | BE27: =DEGREES(IF(BC27<>0,ATAN2(BB27,BC27),0)) -> #DIV/0! | BF27: =BE27*$R$26/360 -> #DIV/0!
K28: DTYie | L28: |Yie| | N28: CF | O28: CFi | P28: CFe | V28: Componente + strati liminari | X28: ='Calcoli matriciali'!$F$14 -> #DIV/0! | Y28: ='Calcoli matriciali'!$G$14 | Z28: =SQRT(X28^2+Y28^2) -> #DIV/0! | AA28: =DEGREES(IF(Y28<>0,ATAN2(X28,Y28),0)) -> 0 | AB28: =AA28*$R$26/360 -> 0 | AC28: ='Calcoli matriciali'!$H$14 | AD28: ='Calcoli matriciali'!$I$14 | AE28: =SQRT(AC28^2+AD28^2) -> 0 | AF28: =DEGREES(IF(AD28<>0,ATAN2(AC28,AD28),0)) -> 0 | AG28: =AF28*$R$26/360 -> 0 | AH28: ='Calcoli matriciali'!$F$16 | AI28: ='Calcoli matriciali'!$G$16 | AJ28: =SQRT(AH28^2+AI28^2) -> 0 | AK28: =DEGREES(IF(AI28<>0,ATAN2(AH28,AI28),0)) -> 0 | AL28: =AK28*$R$26/360 -> 0 | AM28: ='Calcoli matriciali'!$H$16 | AN28: ='Calcoli matriciali'!$I$16 | AO28: =SQRT(AM28^2+AN28^2) -> 0 | AP28: =DEGREES(IF(AN28<>0,ATAN2(AM28,AN28),0)) -> 0 | AQ28: =AP28*$R$26/360 -> 0 | AR28: =-($X28*$AC28+$Y28*$AD28)/($AC28^2+$AD28^2) -> #DIV/0! | AS28: =-($Y28*$AC28-$X28*$AD28)/($AC28^2+$AD28^2) -> #DIV/0! | AT28: =SQRT(AR28^2+AS28^2) -> #DIV/0! | AU28: =DEGREES(IF(AS28<>0,ATAN2(AR28,AS28),0)) -> #DIV/0! | AV28: =AU28*$R$26/360 -> #DIV/0! | AW28: =-($AM28*$AC28+$AN28*$AD28)/($AC28^2+$AD28^2) -> #DIV/0! | AX28: =-($AN28*$AC28-$AM28*$AD28)/($AC28^2+$AD28^2) -> #DIV/0! | AY28: =SQRT(AW28^2+AX28^2) -> #DIV/0! | AZ28: =DEGREES(IF(AX28<>0,ATAN2(AW28,AX28),0)) -> #DIV/0! | BA28: =AZ28*$R$26/360 -> #DIV/0! | BB28: =-$AC28/($AC28^2+$AD28^2) -> #DIV/0! | BC28: =$AD28/($AC28^2+$AD28^2) -> #DIV/0! | BD28: =SQRT(BB28^2+BC28^2) -> #DIV/0! | BE28: =DEGREES(IF(BC28<>0,ATAN2(BB28,BC28),0)) -> #DIV/0! | BF28: =BE28*$R$26/360 -> #DIV/0!
K29: [h] | L29: [W/m2°C] | N29: [kJ/m2°C] | O29: [kJ/m2°C] | P29: [kJ/m2°C]
K30: =$BF$28 -> #DIV/0! | L30: =$BD$28 -> #DIV/0! | N30: =$M$17/1000 -> 0 | O30: =O$17/$K$26/1000 -> 0 | P30: =P$17/$K$26/1000 -> 0 | X30: Z'11 | AC30: Z'12 | AH30: Z'21 | AM30: Z'22 | AR30: Yii = Y'22 = -Z'22/Z'12 | AW30: Yee = Y'11 = -Z'11/Z'12 | BB30: Yei = Y'12 = -1/Z'12
L31: f = |Yie|/U | X31: reale | Y31: immag. | Z31: modulo | AA31: fase | AB31: fase | AC31: reale | AD31: immag. | AE31: modulo | AF31: fase | AG31: fase | AH31: reale | AI31: immag. | AJ31: modulo | AK31: fase | AL31: fase | AM31: reale | AN31: immag. | AO31: modulo | AP31: fase | AQ31: fase | AR31: reale | AS31: immag. | AT31: modulo | AU31: fase | AV31: fase | AW31: reale | AX31: immag. | AY31: modulo | AZ31: fase | BA31: fase | BB31: reale | BC31: immag. | BD31: modulo | BE31: fase | BF31: fase
L32: [-] | X32: [-] | Y32: [-] | Z32: [-] | AA32: [°] | AB32: [h] | AC32: [m2°C/W] | AD32: [m2°C/W] | AE32: [m2°C/W] | AF32: [°] | AG32: [h] | AH32: [W/m2°C] | AI32: [W/m2°C] | AJ32: [W/m2°C] | AK32: [°] | AL32: [h] | AM32: [-] | AN32: [-] | AO32: [-] | AP32: [°] | AQ32: [h] | AR32: [W/m2°C] | AS32: [W/m2°C] | AT32: [W/m2°C] | AU32: [°] | AV32: [h] | AW32: [W/m2°C] | AX32: [W/m2°C] | AY32: [W/m2°C] | AZ32: [°] | BA32: [h] | BB32: [W/m2°C] | BC32: [W/m2°C] | BD32: [W/m2°C] | BE32: [°] | BF32: [h]
L33: =$K$26*$BD$28 -> #DIV/0! | V33: Componente | X33: ='Calcoli matriciali'!$J$20 -> #DIV/0! | Y33: ='Calcoli matriciali'!$K$20 | Z33: =SQRT(X33^2+Y33^2) -> #DIV/0! | AA33: =DEGREES(IF(Y33<>0,ATAN2(X33,Y33),0)) -> 0 | AB33: =AA33*$R$26/360 -> 0 | AC33: ='Calcoli matriciali'!$L$20 | AD33: ='Calcoli matriciali'!$M$20 | AE33: =SQRT(AC33^2+AD33^2) -> 0 | AF33: =DEGREES(IF(AD33<>0,ATAN2(AC33,AD33),0)) -> 0 | AG33: =AF33*$R$26/360 -> 0 | AH33: ='Calcoli matriciali'!$J$22 | AI33: ='Calcoli matriciali'!$K$22 | AJ33: =SQRT(AH33^2+AI33^2) -> 0 | AK33: =DEGREES(IF(AI33<>0,ATAN2(AH33,AI33),0)) -> 0 | AL33: =AK33*$R$26/360 -> 0 | AM33: ='Calcoli matriciali'!$L$22 | AN33: ='Calcoli matriciali'!$M$22 | AO33: =SQRT(AM33^2+AN33^2) -> 0 | AP33: =DEGREES(IF(AN33<>0,ATAN2(AM33,AN33),0)) -> 0 | AQ33: =AP33*$R$26/360 -> 0 | AR33: =-($AM33*$AC33+$AN33*$AD33)/($AC33^2+$AD33^2) -> #DIV/0! | AS33: =-($AN33*$AC33-$AM33*$AD33)/($AC33^2+$AD33^2) -> #DIV/0! | AT33: =SQRT(AR33^2+AS33^2) -> #DIV/0! | AU33: =DEGREES(IF(AS33<>0,ATAN2(AR33,AS33),0)) -> #DIV/0! | AV33: =AU33*$R$26/360 -> #DIV/0! | AW33: =-($X33*$AC33+$Y33*$AD33)/($AC33^2+$AD33^2) -> #DIV/0! | AX33: =-($Y33*$AC33-$X33*$AD33)/($AC33^2+$AD33^2) -> #DIV/0! | AY33: =SQRT(AW33^2+AX33^2) -> #DIV/0! | AZ33: =DEGREES(IF(AX33<>0,ATAN2(AW33,AX33),0)) -> #DIV/0! | BA33: =AZ33*$R$26/360 -> #DIV/0! | BB33: =-$AC33/($AC33^2+$AD33^2) -> #DIV/0! | BC33: =$AD33/($AC33^2+$AD33^2) -> #DIV/0! | BD33: =SQRT(BB33^2+BC33^2) -> #DIV/0! | BE33: =DEGREES(IF(BC33<>0,ATAN2(BB33,BC33),0)) -> #DIV/0! | BF33: =BE33*$R$26/360 -> #DIV/0!
C34: old | D34: old adiab. | E34: new | V34: Componente + strati liminari | X34: ='Calcoli matriciali'!$AT$25 -> #DIV/0! | Y34: ='Calcoli matriciali'!$AU$25 | Z34: =SQRT(X34^2+Y34^2) -> #DIV/0! | AA34: =DEGREES(IF(Y34<>0,ATAN2(X34,Y34),0)) -> 0 | AB34: =AA34*$R$26/360 -> 0 | AC34: ='Calcoli matriciali'!$AV$25 | AD34: ='Calcoli matriciali'!$AW$25 | AE34: =SQRT(AC34^2+AD34^2) -> 0 | AF34: =DEGREES(IF(AD34<>0,ATAN2(AC34,AD34),0)) -> 0 | AG34: =AF34*$R$26/360 -> 0 | AH34: ='Calcoli matriciali'!$AT$27 | AI34: ='Calcoli matriciali'!$AU$27 | AJ34: =SQRT(AH34^2+AI34^2) -> 0 | AK34: =DEGREES(IF(AI34<>0,ATAN2(AH34,AI34),0)) -> 0 | AL34: =AK34*$R$26/360 -> 0 | AM34: ='Calcoli matriciali'!$AV$27 | AN34: ='Calcoli matriciali'!$AW$27 | AO34: =SQRT(AM34^2+AN34^2) -> 0 | AP34: =DEGREES(IF(AN34<>0,ATAN2(AM34,AN34),0)) -> 0 | AQ34: =AP34*$R$26/360 -> 0 | AR34: =-($AM34*$AC34+$AN34*$AD34)/($AC34^2+$AD34^2) -> #DIV/0! | AS34: =-($AN34*$AC34-$AM34*$AD34)/($AC34^2+$AD34^2) -> #DIV/0! | AT34: =SQRT(AR34^2+AS34^2) -> #DIV/0! | AU34: =DEGREES(IF(AS34<>0,ATAN2(AR34,AS34),0)) -> #DIV/0! | AV34: =AU34*$R$26/360 -> #DIV/0! | AW34: =-($X34*$AC34+$Y34*$AD34)/($AC34^2+$AD34^2) -> #DIV/0! | AX34: =-($Y34*$AC34-$X34*$AD34)/($AC34^2+$AD34^2) -> #DIV/0! | AY34: =SQRT(AW34^2+AX34^2) -> #DIV/0! | AZ34: =DEGREES(IF(AX34<>0,ATAN2(AW34,AX34),0)) -> #DIV/0! | BA34: =AZ34*$R$26/360 -> #DIV/0! | BB34: =-$AC34/($AC34^2+$AD34^2) -> #DIV/0! | BC34: =$AD34/($AC34^2+$AD34^2) -> #DIV/0! | BD34: =SQRT(BB34^2+BC34^2) -> #DIV/0! | BE34: =DEGREES(IF(BC34<>0,ATAN2(BB34,BC34),0)) -> #DIV/0! | BF34: =BE34*$R$26/360 -> #DIV/0!
C35: c i | D35: c i | E35: c i | K35: DTYii | L35: |Yii|
C36: [kJ/m2°C] | D36: [kJ/m2°C] | E36: [kJ/m2°C] | K36: [h] | L36: [W/m2°C] | AR36: 1/Yii = 1/Y11 = -Z12/Z11 | AW36: 1/Yee = 1/Y22 = -Z12/Z22
C37: =1/ABS($AS$40)/$S$26/1000 -> #DIV/0! | D37: =1/ABS($AS$52)/$S$26/1000 -> #DIV/0! | E37: =$AT$46/$S$26/1000 -> #DIV/0! | K37: =$AV$28 -> #DIV/0! | L37: =$AT$28 -> #DIV/0! | AR37: reale | AS37: immag. | AT37: modulo | AU37: fase | AV37: fase | AW37: reale | AX37: immag. | AY37: modulo | AZ37: fase | BA37: fase
L38: |Yii|/U | AR38: [m2°C/W] | AS38: [m2°C/W] | AT38: [m2°C/W] | AU38: [°] | AV38: [h] | AW38: [m2°C/W] | AX38: [m2°C/W] | AY38: [m2°C/W] | AZ38: [°] | BA38: [h]
L39: [-] | AP39: Compon. | AR39: =AR27/(AR27^2+AS27^2) -> #DIV/0! | AS39: =-AS27/(AR27^2+AS27^2) -> #DIV/0! | AT39: =SQRT(AR39^2+AS39^2) -> #DIV/0! | AU39: =DEGREES(IF(AS39<>0,ATAN2(AR39,AS39),0)) -> #DIV/0! | AV39: =AU39*$R$26/360 -> #DIV/0! | AW39: =AW27/(AW27^2+AX27^2) -> #DIV/0! | AX39: =-AX27/(AW27^2+AX27^2) -> #DIV/0! | AY39: =SQRT(AW39^2+AX39^2) -> #DIV/0! | AZ39: =DEGREES(IF(AX39<>0,ATAN2(AW39,AX39),0)) -> #DIV/0! | BA39: =AZ39*$R$26/360 -> #DIV/0!
L40: =$K$26*$AT$28 -> #DIV/0! | AP40: Compon. + strati liminari | AR40: =AR28/(AR28^2+AS28^2) -> #DIV/0! | AS40: =-AS28/(AR28^2+AS28^2) -> #DIV/0! | AT40: =SQRT(AR40^2+AS40^2) -> #DIV/0! | AU40: =DEGREES(IF(AS40<>0,ATAN2(AR40,AS40),0)) -> #DIV/0! | AV40: =AU40*$R$26/360 -> #DIV/0! | AW40: =AW28/(AW28^2+AX28^2) -> #DIV/0! | AX40: =-AX28/(AW28^2+AX28^2) -> #DIV/0! | AY40: =SQRT(AW40^2+AX40^2) -> #DIV/0! | AZ40: =DEGREES(IF(AX40<>0,ATAN2(AW40,AX40),0)) -> #DIV/0! | BA40: =AZ40*$R$26/360 -> #DIV/0!
C42: c e | D42: c e | E42: c e | K42: DTYee | L42: |Yee| | AR42: Ammettenza comp. adiabatico Yiiad = (Yii - Yie ) = (1-Z11)/Z12 | AW42: Ammetenza comp. adiabatico Yeead = (Yee - Yie ) = (1-Z22)/Z12
C43: [kJ/m2°C] | D43: [kJ/m2°C] | E43: [kJ/m2°C] | K43: [h] | L43: [W/m2°C] | AR43: reale | AS43: immag. | AT43: modulo | AU43: fase | AV43: fase | AW43: reale | AX43: immag. | AY43: modulo | AZ43: fase | BA43: fase
C44: =1/ABS($AX$40)/$S$26/1000 -> #DIV/0! | D44: =1/ABS($AX$52)/$S$26/1000 -> #DIV/0! | E44: =$AY$46/$S$26/1000 -> #DIV/0! | K44: =$BA$28 -> #DIV/0! | L44: =$AY$28 -> #DIV/0! | AR44: [W/m2°C] | AS44: [W/m2°C] | AT44: [W/m2°C] | AU44: [°] | AV44: [h] | AW44: [W/m2°C] | AX44: [W/m2°C] | AY44: [W/m2°C] | AZ44: [°] | BA44: [h]
L45: |Yee|/U | AP45: Compon. | AR45: =AR27-$BB27 -> #DIV/0! | AS45: =AS27-$BC27 -> #DIV/0! | AT45: =SQRT(AR45^2+AS45^2) -> #DIV/0! | AU45: =DEGREES(IF(AS45<>0,ATAN2(AR45,AS45),0)) -> #DIV/0! | AV45: =AU45*$R$26/360 -> #DIV/0! | AW45: =AW27-$BB27 -> #DIV/0! | AX45: =AX27-$BC27 -> #DIV/0! | AY45: =SQRT(AW45^2+AX45^2) -> #DIV/0! | AZ45: =DEGREES(IF(AX45<>0,ATAN2(AW45,AX45),0)) -> #DIV/0! | BA45: =AZ45*$R$26/360 -> #DIV/0!
...

Sheet Calcoli matriciali
B2: Matrice di trasf. dei singoli strati | D2: Zsi | H2: ZI | L2: ZII | P2: ZIII | T2: ZIV | X2: ZV | AB2: ZVI | AF2: ZVII | AJ2: ZVIII | AN2: ZIX | AR2: ZX | AV2: Zse
D3: ='Calcoli componente'!$X$21 -> 1 | E3: ='Calcoli componente'!$Y$21 -> 0 | F3: ='Calcoli componente'!$AC$21 -> -0.1 | G3: ='Calcoli componente'!$AD$21 -> 0 | H3: ='Calcoli componente'!$X$7 -> #DIV/0! | I3: ='Calcoli componente'!$Y$7 -> #DIV/0! | J3: ='Calcoli componente'!$AC$7 -> #DIV/0! | K3: ='Calcoli componente'!$AD$7 -> #DIV/0! | L3: ='Calcoli componente'!$X$8 -> #DIV/0! | M3: ='Calcoli componente'!$Y$8 -> #DIV/0! | N3: ='Calcoli componente'!$AC$8 -> #DIV/0! | O3: ='Calcoli componente'!$AD$8 -> #DIV/0! | P3: ='Calcoli componente'!$X$9 -> #DIV/0! | Q3: ='Calcoli componente'!$Y$9 -> #DIV/0! | R3: ='Calcoli componente'!$AC$9 -> #DIV/0! | S3: ='Calcoli componente'!$AD$9 -> #DIV/0! | T3: ='Calcoli componente'!$X$10 -> 1 | U3: ='Calcoli componente'!$Y$10 -> 0 | V3: ='Calcoli componente'!$AC$10 -> 0 | W3: ='Calcoli componente'!$AD$10 -> 0 | X3: ='Calcoli componente'!$X$11 -> 1 | Y3: ='Calcoli componente'!$Y$11 -> 0 | Z3: ='Calcoli componente'!$AC$11 -> 0 | AA3: ='Calcoli componente'!$AD$11 -> 0 | AB3: ='Calcoli componente'!$X$12 -> 1 | AC3: ='Calcoli componente'!$Y$12 -> 0 | AD3: ='Calcoli componente'!$AC$12 -> 0 | AE3: ='Calcoli componente'!$AD$12 -> 0 | AF3: ='Calcoli componente'!$X$13 -> 1 | AG3: ='Calcoli componente'!$Y$13 -> 0 | AH3: ='Calcoli componente'!$AC$13 -> 0 | AI3: ='Calcoli componente'!$AD$13 -> 0 | AJ3: ='Calcoli componente'!$X$14 -> 1 | AK3: ='Calcoli componente'!$Y$14 -> 0 | AL3: ='Calcoli componente'!$AC$14 -> 0 | AM3: ='Calcoli componente'!$AD$14 -> 0 | AN3: ='Calcoli componente'!$X$15 -> 1 | AO3: ='Calcoli componente'!$Y$15 -> 0 | AP3: ='Calcoli componente'!$AC$15 -> 0 | AQ3: ='Calcoli componente'!$AD$15 -> 0 | AR3: ='Calcoli componente'!$X$16 -> 1 | AS3: ='Calcoli componente'!$Y$16 -> 0 | AT3: ='Calcoli componente'!$AC$16 -> 0 | AU3: ='Calcoli componente'!$AD$16 -> 0 | AV3: ='Calcoli componente'!$X$22 -> 1 | AW3: ='Calcoli componente'!$Y$22 -> 0 | AX3: ='Calcoli componente'!$AC$22 -> -0.04 | AY3: ='Calcoli componente'!$AD$22 -> 0
D4: =-'Calcoli componente'!$Y$21 -> 0 | E4: ='Calcoli componente'!$X$21 -> 1 | F4: =-'Calcoli componente'!$AD$21 -> 0 | G4: ='Calcoli componente'!$AC$21 -> -0.1 | H4: =-'Calcoli componente'!$Y$7 -> #DIV/0! | I4: ='Calcoli componente'!$X$7 -> #DIV/0! | J4: =-'Calcoli componente'!$AD$7 -> #DIV/0! | K4: ='Calcoli componente'!$AC$7 -> #DIV/0! | L4: =-'Calcoli componente'!$Y$8 -> #DIV/0! | M4: ='Calcoli componente'!$X$8 -> #DIV/0! | N4: =-'Calcoli componente'!$AD$8 -> #DIV/0! | O4: ='Calcoli componente'!$AC$8 -> #DIV/0! | P4: =-'Calcoli componente'!$Y$9 -> #DIV/0! | Q4: ='Calcoli componente'!$X$9 -> #DIV/0! | R4: =-'Calcoli componente'!$AD$9 -> #DIV/0! | S4: ='Calcoli componente'!$AC$9 -> #DIV/0! | T4: =-'Calcoli componente'!$Y$10 -> 0 | U4: ='Calcoli componente'!$X$10 -> 1 | V4: =-'Calcoli componente'!$AD$10 -> 0 | W4: ='Calcoli componente'!$AC$10 -> 0 | X4: =-'Calcoli componente'!$Y$11 -> 0 | Y4: ='Calcoli componente'!$X$11 -> 1 | Z4: =-'Calcoli componente'!$AD$11 -> 0 | AA4: ='Calcoli componente'!$AC$11 -> 0 | AB4: =-'Calcoli componente'!$Y$12 -> 0 | AC4: ='Calcoli componente'!$X$12 -> 1 | AD4: =-'Calcoli componente'!$AD$12 -> 0 | AE4: ='Calcoli componente'!$AC$12 -> 0 | AF4: =-'Calcoli componente'!$Y$13 -> 0 | AG4: ='Calcoli componente'!$X$13 -> 1 | AH4: =-'Calcoli componente'!$AD$13 -> 0 | AI4: ='Calcoli componente'!$AC$13 -> 0 | AJ4: =-'Calcoli componente'!$Y$14 -> 0 | AK4: ='Calcoli componente'!$X$14 -> 1 | AL4: =-'Calcoli componente'!$AD$14 -> 0 | AM4: ='Calcoli componente'!$AC$14 -> 0 | AN4: =-'Calcoli componente'!$Y$15 -> 0 | AO4: ='Calcoli componente'!$X$15 -> 1 | AP4: =-'Calcoli componente'!$AD$15 -> 0 | AQ4: ='Calcoli componente'!$AC$15 -> 0 | AR4: =-'Calcoli componente'!$Y$16 -> 0 | AS4: ='Calcoli componente'!$X$16 -> 1 | AT4: =-'Calcoli componente'!$AD$16 -> 0 | AU4: ='Calcoli componente'!$AC$16 -> 0 | AV4: =-'Calcoli componente'!$Y$22 -> 0 | AW4: ='Calcoli componente'!$X$22 -> 1 | AX4: =-'Calcoli componente'!$AD$22 -> 0 | AY4: ='Calcoli componente'!$AC$22 -> -0.04
D5: ='Calcoli componente'!$AH$21 -> 0 | E5: ='Calcoli componente'!$AI$21 -> 0 | F5: ='Calcoli componente'!$AM$21 -> 1 | G5: ='Calcoli componente'!$AN$21 -> 0 | H5: ='Calcoli componente'!$AH$7 -> #DIV/0! | I5: ='Calcoli componente'!$AI$7 -> #DIV/0! | J5: ='Calcoli componente'!$AM$7 -> #DIV/0! | K5: ='Calcoli componente'!$AN$7 -> #DIV/0! | L5: ='Calcoli componente'!$AH$8 -> #DIV/0! | M5: ='Calcoli componente'!$AI$8 -> #DIV/0! | N5: ='Calcoli componente'!$AM$8 -> #DIV/0! | O5: ='Calcoli componente'!$AN$8 -> #DIV/0! | P5: ='Calcoli componente'!$AH$9 -> #DIV/0! | Q5: ='Calcoli componente'!$AI$9 -> #DIV/0! | R5: ='Calcoli componente'!$AM$9 -> #DIV/0! | S5: ='Calcoli componente'!$AN$9 -> #DIV/0! | T5: ='Calcoli componente'!$AH$10 -> 0 | U5: ='Calcoli componente'!$AI$10 -> 0 | V5: ='Calcoli componente'!$AM$10 -> 1 | W5: ='Calcoli componente'!$AN$10 -> 0 | X5: ='Calcoli componente'!$AH$11 -> 0 | Y5: ='Calcoli componente'!$AI$11 -> 0 | Z5: ='Calcoli componente'!$AM$11 -> 1 | AA5: ='Calcoli componente'!$AN$11 -> 0 | AB5: ='Calcoli componente'!$AH$12 -> 0 | AC5: ='Calcoli componente'!$AI$12 -> 0 | AD5: ='Calcoli componente'!$AM$12 -> 1 | AE5: ='Calcoli componente'!$AN$12 -> 0 | AF5: ='Calcoli componente'!$AH$13 -> 0 | AG5: ='Calcoli componente'!$AI$13 -> 0 | AH5: ='Calcoli componente'!$AM$13 -> 1 | AI5: ='Calcoli componente'!$AN$13 -> 0 | AJ5: ='Calcoli componente'!$AH$14 -> 0 | AK5: ='Calcoli componente'!$AI$14 -> 0 | AL5: ='Calcoli componente'!$AM$14 -> 1 | AM5: ='Calcoli componente'!$AN$14 -> 0 | AN5: ='Calcoli componente'!$AH$15 -> 0 | AO5: ='Calcoli componente'!$AI$15 -> 0 | AP5: ='Calcoli componente'!$AM$15 -> 1 | AQ5: ='Calcoli componente'!$AN$15 -> 0 | AR5: ='Calcoli componente'!$AH$16 -> 0 | AS5: ='Calcoli componente'!$AI$16 -> 0 | AT5: ='Calcoli componente'!$AM$16 -> 1 | AU5: ='Calcoli componente'!$AN$16 -> 0 | AV5: ='Calcoli componente'!$AH$22 -> 0 | AW5: ='Calcoli componente'!$AI$22 -> 0 | AX5: ='Calcoli componente'!$AM$22 -> 1 | AY5: ='Calcoli componente'!$AN$22 -> 0
D6: =-'Calcoli componente'!$AI$21 -> 0 | E6: ='Calcoli componente'!$AH$21 -> 0 | F6: =-'Calcoli componente'!$AN21 -> 0 | G6: ='Calcoli componente'!$AM$21 -> 1 | H6: =-'Calcoli componente'!$AI$7 -> #DIV/0! | I6: ='Calcoli componente'!$AH$7 -> #DIV/0! | J6: =-'Calcoli componente'!$AN$7 -> #DIV/0! | K6: ='Calcoli componente'!$AM$7 -> #DIV/0! | L6: =-'Calcoli componente'!$AI$8 -> #DIV/0! | M6: ='Calcoli componente'!$AH$8 -> #DIV/0! | N6: =-'Calcoli componente'!$AN$8 -> #DIV/0! | O6: ='Calcoli componente'!$AM$8 -> #DIV/0! | P6: =-'Calcoli componente'!$AI$9 -> #DIV/0! | Q6: ='Calcoli componente'!$AH$9 -> #DIV/0! | R6: =-'Calcoli componente'!$AN$9 -> #DIV/0! | S6: ='Calcoli componente'!$AM$9 -> #DIV/0! | T6: =-'Calcoli componente'!$AI$10 -> 0 | U6: ='Calcoli componente'!$AH$10 -> 0 | V6: =-'Calcoli componente'!$AN$10 -> 0 | W6: ='Calcoli componente'!$AM$10 -> 1 | X6: =-'Calcoli componente'!$AI$11 -> 0 | Y6: ='Calcoli componente'!$AH$11 -> 0 | Z6: =-'Calcoli componente'!$AN$11 -> 0 | AA6: ='Calcoli componente'!$AM$11 -> 1 | AB6: =-'Calcoli componente'!$AI$12 -> 0 | AC6: ='Calcoli componente'!$AH$12 -> 0 | AD6: =-'Calcoli componente'!$AN$12 -> 0 | AE6: ='Calcoli componente'!$AM$12 -> 1 | AF6: =-'Calcoli componente'!$AI$13 -> 0 | AG6: ='Calcoli componente'!$AH$13 -> 0 | AH6: =-'Calcoli componente'!$AN$13 -> 0 | AI6: ='Calcoli componente'!$AM$13 -> 1 | AJ6: =-'Calcoli componente'!$AI$14 -> 0 | AK6: ='Calcoli componente'!$AH$14 -> 0 | AL6: =-'Calcoli componente'!$AN$14 -> 0 | AM6: ='Calcoli componente'!$AM$14 -> 1 | AN6: =-'Calcoli componente'!$AI$15 -> 0 | AO6: ='Calcoli componente'!$AH$15 -> 0 | AP6: =-'Calcoli componente'!$AN$15 -> 0 | AQ6: ='Calcoli componente'!$AM$15 -> 1 | AR6: =-'Calcoli componente'!$AI$16 -> 0 | AS6: ='Calcoli componente'!$AH$16 -> 0 | AT6: =-'Calcoli componente'!$AN$16 -> 0 | AU6: ='Calcoli componente'!$AM$16 -> 1 | AV6: =-'Calcoli componente'!$AI$22 -> 0 | AW6: ='Calcoli componente'!$AH$22 -> 0 | AX6: =-'Calcoli componente'!$AN$22 -> 0 | AY6: ='Calcoli componente'!$AM$22 -> 1
B8: Matrice di trasf. del componente dall'interno all'esterno | J8: Z II·Z I | N8: Z III·Z II·Z I | R8: Z IV·Z III·Z II·Z I | V8: ZV·Z IV·Z III·Z II·Z I | Z8: ZVI·ZV·Z IV·Z III·Z II·Z I | AD8: ZVII·ZVI·ZV·Z IV·Z III·Z II·Z I | AH8: ZVIII·ZVII·ZVI·ZV·Z IV·Z III·Z II·Z I | AL8: Z IX·ZVIII·ZVII·ZVI·ZV·Z IV·Z III·Z II·Z I | AP8: Z = ZX·Z IX·ZVIII·ZVII·ZVI·ZV·Z IV·Z III·Z II·Z I | AT8: Zse·Z
J9: {=MMULT(L3:O6,H3:K6)} -> #DIV/0! | N9: {=MMULT(P3:S6,J9:M12)} -> #DIV/0! | R9: {=MMULT(T3:W6,N9:Q12)} -> #DIV/0! | V9: {=MMULT(X3:AA6,R9:U12)} -> #DIV/0! | Z9: {=MMULT(AB3:AE6,V9:Y12)} -> #DIV/0! | AD9: {=MMULT(AF3:AI6,Z9:AC12)} -> #DIV/0! | AH9: {=MMULT(AJ3:AM6,AD9:AG12)} -> #DIV/0! | AL9: {=MMULT(AN3:AQ6,AH9:AK12)} -> #DIV/0! | AP9: {=MMULT(AR3:AU6,AL9:AO12)} -> #DIV/0! | AT9: {=MMULT(AV3:AY6,AP9:AS12)} -> #DIV/0!
F13: Zse · Z · Zsi
F14: {=MMULT(AT9:AW12,D3:G6)} -> #DIV/0!
B19: Matrice di trasf. del componente dall'esterno all'interno | F19: Zsi · Z' | J19: Z' = Z I·Z II·Z III·Z IV·ZV·ZVI·ZVII·ZVIII·Z IX·ZX | N19: Z II·Z III·Z IV·ZV·ZVI·ZVII·ZVIII·Z IX·ZX | R19: Z III·Z IV·ZV·ZVI·ZVII·ZVIII·Z IX·ZX | V19: Z IV·ZV·ZVI·ZVII·ZVIII·Z IX·ZX | Z19: ZV·ZVI·ZVII·ZVIII·Z IX·ZX | AD19: ZVI·ZVII·ZVIII·Z IX·ZX | AH19: ZVII·ZVIII·Z IX·ZX | AL19: ZVIII·Z IX·ZX | AP19: Z IX·ZX
F20: {=MMULT(D3:G6,J20:M23)} -> #DIV/0! | J20: {=MMULT(H3:K6,N20:Q23)} -> #DIV/0! | N20: {=MMULT(L3:O6,R20:U23)} -> #DIV/0! | R20: {=MMULT(P3:S6,V20:Y23)} -> #DIV/0! | V20: {=MMULT(T3:W6,Z20:AC23)} -> 1 | W20: 0 | X20: 0 | Y20: 0 | Z20: {=MMULT(X3:AA6,AD20:AG23)} -> 1 | AA20: 0 | AB20: 0 | AC20: 0 | AD20: {=MMULT(AB3:AE6,AH20:AK23)} -> 1 | AE20: 0 | AF20: 0 | AG20: 0 | AH20: {=MMULT(AF3:AI6,AL20:AO23)} -> 1 | AI20: 0 | AJ20: 0 | AK20: 0 | AL20: {=MMULT(AJ3:AM6,AP20:AS23)} -> 1 | AM20: 0 | AN20: 0 | AO20: 0 | AP20: {=MMULT(AN3:AQ6,AR3:AU6)} -> 1 | AQ20: 0 | AR20: 0 | AS20: 0
V21: 0 | W21: 1 | X21: 0 | Y21: 0 | Z21: 0 | AA21: 1 | AB21: 0 | AC21: 0 | AD21: 0 | AE21: 1 | AF21: 0 | AG21: 0 | AH21: 0 | AI21: 1 | AJ21: 0 | AK21: 0 | AL21: 0 | AM21: 1 | AN21: 0 | AO21: 0 | AP21: 0 | AQ21: 1 | AR21: 0 | AS21: 0
V22: 0 | W22: 0 | X22: 1 | Y22: 0 | Z22: 0 | AA22: 0 | AB22: 1 | AC22: 0 | AD22: 0 | AE22: 0 | AF22: 1 | AG22: 0 | AH22: 0 | AI22: 0 | AJ22: 1 | AK22: 0 | AL22: 0 | AM22: 0 | AN22: 1 | AO22: 0 | AP22: 0 | AQ22: 0 | AR22: 1 | AS22: 0
V23: 0 | W23: 0 | X23: 0 | Y23: 1 | Z23: 0 | AA23: 0 | AB23: 0 | AC23: 1 | AD23: 0 | AE23: 0 | AF23: 0 | AG23: 1 | AH23: 0 | AI23: 0 | AJ23: 0 | AK23: 1 | AL23: 0 | AM23: 0 | AN23: 0 | AO23: 1 | AP23: 0 | AQ23: 0 | AR23: 0 | AS23: 1
AT24: Zsi · Z' · Zse
AT25: {=MMULT(F20:I23,AV3:AY6)} -> #DIV/0!

Sheet Condensa
B2: Città | C2: Zona climatica
B3: Torino | C3: =DGET(Temperatura!$B$1:$O$102,"Zona climatica",Condensa!$B$2:$B$3) -> E
E5: Gennaio | F5: Febbraio | G5: Marzo | H5: Aprile | I5: Maggio | J5: Giugno | K5: Luglio | L5: Agosto | M5: Settembre | N5: Ottobre | O5: Novembre | P5: Dicembre
B6: Temperatura esterna | C6: θe | D6: [°C] | E6: =DGET(Temperatura!$B$1:$O$102,"Gen",Condensa!$B$2:$B$3) -> 0.4 | F6: =DGET(Temperatura!$B$1:$O$102,"Feb",Condensa!$B$2:$B$3) -> 3.2 | G6: =DGET(Temperatura!$B$1:$O$102,"Mar",Condensa!$B$2:$B$3) -> 8.2 | H6: =DGET(Temperatura!$B$1:$O$102,"Apr",Condensa!$B$2:$B$3) -> 12.7 | I6: =DGET(Temperatura!$B$1:$O$102,"Mag",Condensa!$B$2:$B$3) -> 16.7 | J6: =DGET(Temperatura!$B$1:$O$102,"Giu",Condensa!$B$2:$B$3) -> 21.1 | K6: =DGET(Temperatura!$B$1:$O$102,"Lug",Condensa!$B$2:$B$3) -> 23.3 | L6: =DGET(Temperatura!$B$1:$O$102,"Ago",Condensa!$B$2:$B$3) -> 22.6 | M6: =DGET(Temperatura!$B$1:$O$102,"Set",Condensa!$B$2:$B$3) -> 18.8 | N6: =DGET(Temperatura!$B$1:$O$102,"Ott",Condensa!$B$2:$B$3) -> 12.6 | O6: =DGET(Temperatura!$B$1:$O$102,"Nov",Condensa!$B$2:$B$3) -> 6.8 | P6: =DGET(Temperatura!$B$1:$O$102,"Dic",Condensa!$B$2:$B$3) -> 2
B7: Pressione di vapore esterna | C7: pe | D7: [Pa] | E7: =DGET('Pressione vapore'!$B$1:$N$102,"Gen",Condensa!$B$2:$B$3) -> 516 | F7: =DGET('Pressione vapore'!$B$1:$N$102,"Feb",Condensa!$B$2:$B$3) -> 606 | G7: =DGET('Pressione vapore'!$B$1:$N$102,"Mar",Condensa!$B$2:$B$3) -> 583 | H7: =DGET('Pressione vapore'!$B$1:$N$102,"Apr",Condensa!$B$2:$B$3) -> 804 | I7: =DGET('Pressione vapore'!$B$1:$N$102,"Mag",Condensa!$B$2:$B$3) -> 1235 | J7: =DGET('Pressione vapore'!$B$1:$N$102,"Giu",Condensa!$B$2:$B$3) -> 1702 | K7: =DGET('Pressione vapore'!$B$1:$N$102,"Lug",Condensa!$B$2:$B$3) -> 1837 | L7: =DGET('Pressione vapore'!$B$1:$N$102,"Ago",Condensa!$B$2:$B$3) -> 1953 | M7: =DGET('Pressione vapore'!$B$1:$N$102,"Set",Condensa!$B$2:$B$3) -> 1504 | N7: =DGET('Pressione vapore'!$B$1:$N$102,"Ott",Condensa!$B$2:$B$3) -> 1180 | O7: =DGET('Pressione vapore'!$B$1:$N$102,"Nov",Condensa!$B$2:$B$3) -> 841 | P7: =DGET('Pressione vapore'!$B$1:$N$102,"Dic",Condensa!$B$2:$B$3) -> 606
B8: Umidità relativa esterna | C8: je | D8: [%] | E8: =E$7/pvs_t(E$6) -> #NAME? | F8: =F$7/pvs_t(F$6) -> #NAME? | G8: =G$7/pvs_t(G$6) -> #NAME? | H8: =H$7/pvs_t(H$6) -> #NAME? | I8: =I$7/pvs_t(I$6) -> #NAME? | J8: =J$7/pvs_t(J$6) -> #NAME? | K8: =K$7/pvs_t(K$6) -> #NAME? | L8: =L$7/pvs_t(L$6) -> #NAME? | ... P8: =P$7/pvs_t(P$6) -> #NAME?
B9: Temperatura interna | C9: θi | D9: [°C] | E9: =MAX(20,E6) -> 20 | F9: =MAX(20,F6) -> 20 | G9: =MAX(20,G6) -> 20 | H9: =MAX(20,H6) -> 20 | I9: =MAX(20,I6) -> 20 | J9: =MAX(20,J6) -> 21.1 | K9: =MAX(20,K6) -> 23.3 | L9: =MAX(20,L6) -> 22.6 | ... P9: =MAX(20,P6) -> 20
B10: Differenza pressione di vapore | C10: Δp | D10: [Pa] | E10: =IF(E$6<=0,$Q10,IF(E$6>=20,0,$Q10*(1-E$6/20))) -> 793.8 | F10: =IF(F$6<=0,$Q10,IF(F$6>=20,0,$Q10*(1-F$6/20))) -> 680.4 | G10: =IF(G$6<=0,$Q10,IF(G$6>=20,0,$Q10*(1-G$6/20))) -> 477.9 | H10: =IF(H$6<=0,$Q10,IF(H$6>=20,0,$Q10*(1-H$6/20))) -> 295.65 | I10: =IF(I$6<=0,$Q10,IF(I$6>=20,0,$Q10*(1-I$6/20))) -> 133.65 | J10: =IF(J$6<=0,$Q10,IF(J$6>=20,0,$Q10*(1-J$6/20))) -> 0 | K10: =IF(K$6<=0,$Q10,IF(K$6>=20,0,$Q10*(1-K$6/20))) -> 0 | L10: =IF(L$6<=0,$Q10,IF(L$6>=20,0,$Q10*(1-L$6/20))) -> 0 | ... P10: =IF(P$6<=0,$Q10,IF(P$6>=20,0,$Q10*(1-P$6/20))) -> 729 | Q10: 810 | R10: Δpmax
B11: Pressione di vapore interna | C11: pi | D11: [Pa] | E11: =E$7+E$10*1.1 -> 1389.18 | F11: =F$7+F$10*1.1 -> 1354.44 | G11: =G$7+G$10*1.1 -> 1108.69 | H11: =H$7+H$10*1.1 -> 1129.215 | I11: =I$7+I$10*1.1 -> 1382.015 | J11: =J$7+J$10*1.1 -> 1702 | K11: =K$7+K$10*1.1 -> 1837 | L11: =L$7+L$10*1.1 -> 1953 | ... P11: =P$7+P$10*1.1 -> 1407.9
B12: Umidità relativa interna | C12: ji | D12: [%] | E12: =E$11/pvs_t(E$9) -> #NAME? | F12: =F$11/pvs_t(F$9) -> #NAME? | G12: =G$11/pvs_t(G$9) -> #NAME? | H12: =H$11/pvs_t(H$9) -> #NAME? | I12: =I$11/pvs_t(I$9) -> #NAME? | J12: =J$11/pvs_t(J$9) -> #NAME? | K12: =K$11/pvs_t(K$9) -> #NAME? | L12: =L$11/pvs_t(L$9) -> #NAME? | ... P12: =P$11/pvs_t(P$9) -> #NAME?
B13: Temperatura superficiale min. | C13: θsi,min | D13: [°C] | E13: =tsat(E11/0.8) -> #NAME? | F13: =tsat(F11/0.8) -> #NAME? | G13: =tsat(G11/0.8) -> #NAME? | H13: =tsat(H11/0.8) -> #NAME? | I13: =tsat(I11/0.8) -> #NAME? | J13: =tsat(J11/0.8) -> #NAME? | K13: =tsat(K11/0.8) -> #NAME? | L13: =tsat(L11/0.8) -> #NAME? | ... P13: =tsat(P11/0.8) -> #NAME?
B14: Fattore di temperatura minimo | C14: fRsi,min | D14: [-] | E14: =IF(E13>E6,(E13-E6)/(E9-E6),0) -> #NAME? | F14: =IF(F13>F6,(F13-F6)/(F9-F6),0) -> #NAME? | G14: =IF(G13>G6,(G13-G6)/(G9-G6),0) -> #NAME? | H14: =IF(H13>H6,(H13-H6)/(H9-H6),0) -> #NAME? | I14: =IF(I13>I6,(I13-I6)/(I9-I6),0) -> #NAME? | J14: =IF(J13>J6,(J13-J6)/(J9-J6),0) -> #NAME? | K14: =IF(K13>K6,(K13-K6)/(K9-K6),0) -> #NAME? | L14: =IF(L13>L6,(L13-L6)/(L9-L6),0) -> #NAME? | ... P14: =IF(P13>P6,(P13-P6)/(P9-P6),0) -> #NAME? | Q14: =IF(Glaser!$K$20>MAX(Condensa!E14:P14),"NO COND. SUP.","SI COND. SUP.") -> #NAME?
B15: Massa di vapore condensata | C15: mcond | D15: [g/m2] | E15: {=INDEX(Glaser!$K$20:$CP$20,1,7*(imese(Condensa!E$5)-1)+7)*ngiorni(imese(Condensa!E$5))*24*3600*1000} -> #NAME? | F15: {=INDEX(Glaser!$K$20:$CP$20,1,7*(imese(Condensa!F$5)-1)+7)*ngiorni(imese(Condensa!F$5))*24*3600*1000} -> #NAME? | G15: {=INDEX(Glaser!$K$20:$CP$20,1,7*(imese(Condensa!G$5)-1)+7)*ngiorni(imese(Condensa!G$5))*24*3600*1000} -> #NAME? | H15: {=INDEX(Glaser!$K$20:$CP$20,1,7*(imese(Condensa!H$5)-1)+7)*ngiorni(imese(Condensa!H$5))*24*3600*1000} -> #NAME? | I15: {=INDEX(Glaser!$K$20:$CP$20,1,7*(imese(Condensa!I$5)-1)+7)*ngiorni(imese(Condensa!I$5))*24*3600*1000} -> #NAME? | J15: {=INDEX(Glaser!$K$20:$CP$20,1,7*(imese(Condensa!J$5)-1)+7)*ngiorni(imese(Condensa!J$5))*24*3600*1000} -> #NAME? | K15: {=INDEX(Glaser!$K$20:$CP$20,1,7*(imese(Condensa!K$5)-1)+7)*ngiorni(imese(Condensa!K$5))*24*3600*1000} -> #NAME? | L15: {=INDEX(Glaser!$K$20:$CP$20,1,7*(imese(Condensa!L$5)-1)+7)*ngiorni(imese(Condensa!L$5))*24*3600*1000} -> #NAME? | ... P15: {=INDEX(Glaser!$K$20:$CP$20,1,7*(imese(Condensa!P$5)-1)+7)*ngiorni(imese(Condensa!P$5))*24*3600*1000} -> #NAME? | Q15: =IF(MAX(Condensa!E15:P15)<=0.05,"NO COND. INT.","SI COND. INT.") -> #NAME?
B17: Mese
B18: Gennaio

Sheet Glaser
